Workbook

Sheet references
A1: reference_ID | B1: reference_short | C1: reference_year | D1: reference_full
A2: 14 | B2: Yang et al 2021 | C2: 2021 | D2: Yang, C., Rooney, A.D., et al. 2021. The tempo of Ediacaran evolution. Science Advances, 7, eabi9643, https://doi.org/10.1126/sciadv.abi9643.
A3: 17 | B3: Zhu et al 2013 | C3: 2013 | D3: Zhu, B., Becker, H., Jiang, S.-Y., Pi, D.-H., Fischer-Gödde, M. and Yang, J.-H. 2013. Re–Os geochronology of black shales from the Neoproterozoic Doushantuo Formation, Yangtze platform, South China. Precambrian Research, 225, 67–76, https://doi.org/10.1016/j.precamres.2012.02.002.
A4: 20 | B4: Calver et al 2004 | C4: 2004 | D4: Calver, C.R., Black, L.P., Everard, J.L. and Seymour, D.B. 2004. U-Pb zircon age constraints on late Neoproterozoic glaciation in Tasmania. Geology, 32, 893–896, https://doi.org/10.1130/G20713.1.
A5: 23 | B5: Pu et al 2016 | C5: 2016 | D5: Pu, J.P., Bowring, S.A., et al. 2016. Dodging snowballs: Geochronology of the Gaskiers glaciation and the first appearance of the Ediacaran biota. Geology, 44, 955–958, https://doi.org/10.1130/G38284.1.
A6: 25 | B6: Rooney et al 2020 | C6: 2020 | D6: Rooney, A.D., Cantine, M.D., et al. 2020. Calibrating the coevolution of Ediacaran life and environment. Proceedings of the National Academy of Sciences, https://doi.org/10.1073/pnas.2002918117.
A7: 27 | B7: Srodon et al 2023 | C7: 2023 | D7: Środoń, J., Condon, D.J., et al. 2023. Ages of the Ediacaran Volyn-Brest trap volcanism, glaciations, paleosols, Podillya Ediacaran soft-bodied organisms, and the Redkino-Kotlin boundary (East European Craton) constrained by zircon single grain U-Pb dating. Precambrian Research, 386, 106962, https://doi.org/10.1016/j.precamres.2023.106962.
A8: 28 | B8: Thomas et al 2002 | C8: 2002 | D8: Thomas, R.J., Chevallier, L.P., et al. 2002. Precambrian evolution of the Sirwa Window, Anti-Atlas Orogen, Morocco. Precambrian Research, 118, 1–57, https://doi.org/10.1016/S0301-9268(02)00075-X.
A9: 29 | B9: Thompson & Bowring 2000 | C9: 2000 | D9: Thompson, M.D. and Bowring, S.A. 2000. Age of the Squantum “tillite,” Boston Basin, Massachusetts; U-Pb zircon constraints on terminal Neoproterozoic glaciation. American Journal of Science, 300, 630–655, https://doi.org/10.2475/ajs.300.8.630.
A10: 31 | B10: Nelson et al 2022 | C10: 2022 | D10: Nelson, L.L., Ramezani, J., et al. 2022. Pushing the boundary: A calibrated Ediacaran-Cambrian stratigraphic record from the Nama Group in northwestern Republic of South Africa. Earth and Planetary Science Letters, 580, 117396, https://doi.org/10.1016/j.epsl.2022.117396.
A11: 32 | B11: Miller et al 2008 | C11: 2008 | D11: Miller, N., Johnson, P. and Stern, B. 2008. Marine versus non-marine environments for the Jibalah Group, NW Arabian shield: A sedimentologic and geochemical survey and report of possible metazoa in the Dhaiqa formation. Arabian Journal for Science and Engineering, 33, 55–77.
A12: 34 | B12: Letsch et al 2018 | C12: 2018 | D12: Letsch, D., Large, S.J.E., Buechi, M.W., Winkler, W. and von Quadt, A. 2018. Ediacaran glaciations of the west African Craton – Evidence from Morocco. Precambrian Research, 310, 17–38, https://doi.org/10.1016/j.precamres.2018.02.015.
A13: 36 | B13: Linnemann et al 2018 | C13: 2018 | D13: Linnemann, U., Pidal, A.P., et al. 2018. A ~565 Ma old glaciation in the Ediacaran of peri-Gondwanan West Africa. International Journal of Earth Sciences, 107, 885–911, https://doi.org/10.1007/s00531-017-1520-7.
... A167: 351 | B167: Corkeron & George 2001 | C167: 2001 | D167: Corkeron, M.L. and George, A.D. 2001. Glacial incursion on a Neoproterozoic carbonate platform in the Kimberley region, Australia. GSA Bulletin, 113, 1121–1132, https://doi.org/10.1130/0016-7606(2001)113%253C1121:GIOANC%253E2.0.CO;2.

Sheet meih_occurrences
A1: csl_occurrence_id | B1: deposit_id | C1: deposit_name | D1: likely_interval | E1: section_id | F1: section_name | G1: section_longitude | H1: section_latitude | I1: composite_section_id | J1: composite_section_name | K1: composite_longitude | L1: composite_latitude | M1: csl_type | N1: supergroup | O1: group | P1: subgroup | Q1: formation | R1: member | S1: unit | T1: deposit_synonyms_correlatives | U1: reference1 | V1: reference2 | W1: reference3 | X1: reference4 | Y1: reference5 | Z1: reference6 | AA1: reference7 | AB1: reference8
A2: 1 | B2: =_xlfn.XLOOKUP(C2, csl_deposits!B:B, csl_deposits!A:A, "NA", 0,1) -> 38 | C2: Izdar Member | D2: MEIH | E2: 155 | F2: Ansra | G2: -7.43 | H2: 30.52 | I2: 302 | J2: Anti-Atlas Mountains | K2: -7.6114185 | L2: 30.509645 | M2: diamictite | N2: PIII | R2: Izdar | U2: Letsch et al 2018
A3: 2 | B3: =_xlfn.XLOOKUP(C3, csl_deposits!B:B, csl_deposits!A:A, "NA", 0,1) -> 38 | C3: Izdar Member | D3: MEIH | E3: 156 | F3: Taghdout | G3: -7.27 | H3: 30.72 | I3: 302 | J3: Anti-Atlas Mountains | K3: -7.6114185 | L3: 30.509645 | M3: diamictite | N3: PIII | R3: Izdar | U3: Letsch et al 2018
A4: 9 | B4: =_xlfn.XLOOKUP(C4, csl_deposits!B:B, csl_deposits!A:A, "NA", 0,1) -> 77 | C4: Tiddiline Group | D4: MEIH | E4: 154 | F4: Ait Ahmane | G4: -6.51 | H4: 30.56 | I4: 302 | J4: Anti-Atlas Mountains | K4: -7.6114185 | L4: 30.509645 | M4: diamictite | N4: PIII | O4: Tiddiline | S4: Tiddiline diamictite | U4: Inglis et al 2004 | V4: Letsch et al 2018
A5: 10 | B5: =_xlfn.XLOOKUP(C5, csl_deposits!B:B, csl_deposits!A:A, "NA", 0,1) -> 77 | C5: Tiddiline Group | D5: MEIH | E5: 275 | F5: Bou Azzer | G5: -6.9 | H5: 30.42 | I5: 302 | J5: Anti-Atlas Mountains | K5: -7.6114185 | L5: 30.509645 | M5: diamictite | N5: PIII | O5: Tiddiline | S5: Tiddiline diamictite | U5: Letsch et al 2018
A6: 11 | B6: =_xlfn.XLOOKUP(C6, csl_deposits!B:B, csl_deposits!A:A, "NA", 0,1) -> 77 | C6: Tiddiline Group | D6: MEIH | E6: 157 | F6: Tizwat | G6: -7.56 | H6: 30.76 | I6: 302 | J6: Anti-Atlas Mountains | K6: -7.6114185 | L6: 30.509645 | M6: diamictite | N6: PIII | O6: Tiddiline | S6: Tiddiline diamictite | U6: Letsch et al 2018
A7: 12 | B7: =_xlfn.XLOOKUP(C7, csl_deposits!B:B, csl_deposits!A:A, "NA", 0,1) -> 77 | C7: Tiddiline Group | D7: MEIH | E7: 276 | F7: Timzioura | G7: -8.48 | H7: 30.24 | I7: 302 | J7: Anti-Atlas Mountains | K7: -7.6114185 | L7: 30.509645 | M7: diamictite | N7: PIII | O7: Tiddiline | S7: Tiddiline diamictite | U7: Letsch et al 2018
A8: 13 | B8: =_xlfn.XLOOKUP(C8, csl_deposits!B:B, csl_deposits!A:A, "NA", 0,1) -> 1 | C8: Antaq Polymictic Conglomerate | D8: MEIH | E8: 305 | F8: Antaq Basin | G8: 44.22556 | H8: 23.71837 | I8: 305 | J8: Antaq Basin | K8: 44.22556 | L8: 23.71837 | M8: diamictite | O8: Jibalah | Q8: Rubtayn | S8: Antaq Polymictic Conglomerate | U8: Al-Husseini 2011 | V8: Al-Husseini 2014 | W8: Nettle et al 2014
A9: 18 | B9: =_xlfn.XLOOKUP(C9, csl_deposits!B:B, csl_deposits!A:A, "NA", 0,1) -> 14 | C9: Croles Hill diamictite | D9: MEIH | E9: 151 | F9: Robbins Passage | G9: 144.86249 | H9: -40.743828 | I9: 310 | J9: Tasmania | K9: 144.80629 | L9: -40.772983 | M9: diamictite | O9: Togari | P9: Kanunnah | Q9: Croles Hill | U9: Brown 1986a | V9: Brown 1986b | W9: Crawford & Berry 1992 | X9: Calver & Walter 2000 | Y9: Calver et al 2004 | Z9: Everard et al 2007 | AA9: Mulder et al 2020
A10: 28 | B10: =_xlfn.XLOOKUP(C10, csl_deposits!B:B, csl_deposits!A:A, "NA", 0,1) -> 26 | C10: Gaskiers Formation | D10: MEIH | E10: 152 | F10: St Marys | G10: -53.590889 | H10: 46.923334 | I10: 323 | J10: Avalon Peninsula | K10: -53.321125 | L10: 47.322524 | M10: diamictite | O10: Conception | Q10: Gaskiers | U10: Eyles & Eyles 1989 | V10: Carto & Eyles 2011a | W10: Pu et al 2016 | X10: Fitzgerald et al 2024
A11: 29 | B11: =_xlfn.XLOOKUP(C11, csl_deposits!B:B, csl_deposits!A:A, "NA", 0,1) -> 26 | C11: Gaskiers Formation | D11: MEIH | E11: 259 | F11: Great Colinet Island | G11: -53.74 | H11: 47.04 | I11: 323 | J11: Avalon Peninsula | K11: -53.321125 | L11: 47.322524 | M11: diamictite | O11: Conception | Q11: Gaskiers | U11: Eyles & Eyles 1989 | V11: Carto & Eyles 2011a | W11: Pu et al 2016 | X11: Fitzgerald et al 2024
A12: 30 | B12: =_xlfn.XLOOKUP(C12, csl_deposits!B:B, csl_deposits!A:A, "NA", 0,1) -> 26 | C12: Gaskiers Formation | D12: MEIH | E12: 260 | F12: North Point Bay | G12: -53.65 | H12: 46.98 | I12: 323 | J12: Avalon Peninsula | K12: -53.321125 | L12: 47.322524 | M12: diamictite | O12: Conception | Q12: Gaskiers | U12: Eyles & Eyles 1989 | V12: Carto & Eyles 2011a | W12: Pu et al 2016 | X12: Fitzgerald et al 2024
A13: 31 | B13: =_xlfn.XLOOKUP(C13, csl_deposits!B:B, csl_deposits!A:A, "NA", 0,1) -> 50 | C13: Mall Bay Formation | D13: MEIH | E13: 259 | F13: Great Colinet Island | G13: -53.74 | H13: 47.04 | I13: 323 | J13: Avalon Peninsula | K13: -53.321125 | L13: 47.322524 | M13: lonestones | O13: Conception | Q13: Mall Bay | S13: upper Mall Bay | U13: Krogh et al 1988 | V13: Pu et al 2016 | W13: Fitzgerald et al 2024
A14: 32 | B14: =_xlfn.XLOOKUP(C14, csl_deposits!B:B, csl_deposits!A:A, "NA", 0,1) -> 79 | C14: Trinity diamictite | D14: MEIH | E14: 277 | F14: Trinity Bay | G14: -53.37978 | H14: 48.376619 | I14: 325 | J14: Bonavista Peninsula | K14: -53.578495 | L14: 48.357598 | M14: diamictite | O14: Musgravetown | Q14: Rocky Harbour | S14: Trinity diamictite | T14: Trinity facies | U14: Normore 2011 | V14: Pu et al 2016
A15: 33 | B15: =_xlfn.XLOOKUP(C15, csl_deposits!B:B, csl_deposits!A:A, "NA", 0,1) -> 79 | C15: Trinity diamictite | D15: MEIH | E15: 278 | F15: Trinity Pond | G15: -53.43 | H15: 48.41 | I15: 325 | J15: Bonavista Peninsula | K15: -53.578495 | L15: 48.357598 | M15: diamictite | O15: Musgravetown | Q15: Rocky Harbour | S15: Trinity diamictite | T15: Trinity facies | U15: Pu et al 2016
A16: 34 | B16: =_xlfn.XLOOKUP(C16, csl_deposits!B:B, csl_deposits!A:A, "NA", 0,1) -> 79 | C16: Trinity diamictite | D16: MEIH | E16: 279 | F16: Old Bonaventure | G16: -53.43 | H16: 48.29 | I16: 325 | J16: Bonavista Peninsula | K16: -53.578495 | L16: 48.357598 | M16: diamictite | O16: Musgravetown | Q16: Rocky Harbour | S16: Trinity diamictite | T16: Trinity facies | U16: Pu et al 2016
A17: 35 | B17: =_xlfn.XLOOKUP(C17, csl_deposits!B:B, csl_deposits!A:A, "NA", 0,1) -> 79 | C17: Trinity diamictite | D17: MEIH | E17: 280 | F17: Cat Cove | G17: -53.43 | H17: 48.28 | I17: 325 | J17: Bonavista Peninsula | K17: -53.578495 | L17: 48.357598 | M17: diamictite | O17: Musgravetown | Q17: Rocky Harbour | S17: Trinity diamictite | T17: Trinity facies | U17: Pu et al 2016
A18: 43 | B18: =_xlfn.XLOOKUP(C18, csl_deposits!B:B, csl_deposits!A:A, "NA", 0,1) -> 44 | C18: Las Ventanas Formation | D18: MEIH | E18: 264 | F18: Burgueno Quarry | G18: -55.26 | H18: -34.71 | I18: 330 | J18: Maldonado | K18: -55.26 | L18: -34.71 | M18: diamictite | O18: Maldonado | Q18: Las Ventanas | U18: Sanchez Bettucci & Linares 1996 | V18: Blanco & Gaucher 2005 | W18: Oyhantcabal et al 2006 | X18: Gaucher et al 2008 | Y18: Poire & Gaucher 2009 | Z18: Pecoits et al 2011
A19: 44 | B19: =_xlfn.XLOOKUP(C19, csl_deposits!B:B, csl_deposits!A:A, "NA", 0,1) -> 44 | C19: Las Ventanas Formation | D19: MEIH | E19: 266 | F19: CUCPSA Quarry | G19: -55.28 | H19: -34.37 | I19: 330 | J19: Maldonado | K19: -55.26 | L19: -34.71 | M19: diamictite | O19: Maldonado | Q19: Las Ventanas | U19: Gaucher et al 2008
A20: 45 | B20: =_xlfn.XLOOKUP(C20, csl_deposits!B:B, csl_deposits!A:A, "NA", 0,1) -> 44 | C20: Las Ventanas Formation | D20: MEIH | E20: 268 | F20: Pan de Azucar | G20: -55.24 | H20: -34.77 | I20: 330 | J20: Maldonado | K20: -55.26 | L20: -34.71 | M20: diamictite | O20: Maldonado | Q20: Las Ventanas | U20: Oyhantcabal et al 2007 | V20: Gaucher et al 2008
A21: 46 | B21: =_xlfn.XLOOKUP(C21, csl_deposits!B:B, csl_deposits!A:A, "NA", 0,1) -> 44 | C21: Las Ventanas Formation | D21: MEIH | E21: 267 | F21: Piriapolis | G21: -55.28 | H21: -34.88 | I21: 330 | J21: Maldonado | K21: -55.26 | L21: -34.71 | M21: diamictite | O21: Maldonado | Q21: Las Ventanas | U21: Bossi et al 1993 | V21: Gaucher et al 2008
A22: 47 | B22: =_xlfn.XLOOKUP(C22, csl_deposits!B:B, csl_deposits!A:A, "NA", 0,1) -> 44 | C22: Las Ventanas Formation | D22: MEIH | E22: 265 | F22: R60-R81 | G22: -55.27 | H22: -34.53 | I22: 330 | J22: Maldonado | K22: -55.26 | L22: -34.71 | M22: diamictite | O22: Maldonado | Q22: Las Ventanas | U22: Mallmann et al 2007
A23: 48 | B23: =_xlfn.XLOOKUP(C23, csl_deposits!B:B, csl_deposits!A:A, "NA", 0,1) -> 9 | C23: Bunyeroo Formation | D23: MEIH | E23: 249 | F23: Wilcolo Creek | G23: 138.56 | H23: -31.43 | I23: 233 | J23: Flinders Ranges | K23: 138.66497 | L23: -31.372568 | M23: lonestone | O23: Wilpena | Q23: Bunyeroo | U23: Webb et al 1983 | V23: Haines 1986 | W23: Compston et al 1987 | X23: Young 1995 | Y23: Wallace et al 1996 | Z23: Gostin et al 2010 | AA23: Williams & Schmidt 2018 | AB23: Williams & Schmidt 2021
A24: 49 | B24: =_xlfn.XLOOKUP(C24, csl_deposits!B:B, csl_deposits!A:A, "NA", 0,1) -> 9 | C24: Bunyeroo Formation | D24: MEIH | E24: 249 | F24: Wilcolo Creek | G24: 138.56 | H24: -31.43 | I24: 233 | J24: Flinders Ranges | K24: 138.66497 | L24: -31.372568 | M24: granule cluster | O24: Wilpena | Q24: Bunyeroo | U24: Webb et al 1983 | V24: Haines 1986 | W24: Compston et al 1987 | X24: Young 1995 | Y24: Wallace et al 1996 | Z24: Gostin et al 2010 | AA24: Williams & Schmidt 2018 | AB24: Williams & Schmidt 2021
A25: 50 | B25: =_xlfn.XLOOKUP(C25, csl_deposits!B:B, csl_deposits!A:A, "NA", 0,1) -> 9 | C25: Bunyeroo Formation | D25: MEIH | E25: 250 | F25: Parachilna Gorge | G25: 138.53 | H25: -31.14 | I25: 233 | J25: Flinders Ranges | K25: 138.66497 | L25: -31.372568 | M25: lonestone | O25: Wilpena | Q25: Bunyeroo | U25: Webb et al 1983 | V25: Haines 1986 | W25: Compston et al 1987 | X25: Young 1995 | Y25: Wallace et al 1996 | Z25: Gostin et al 2010 | AA25: Williams & Schmidt 2018 | AB25: Williams & Schmidt 2021
A26: 51 | B26: =_xlfn.XLOOKUP(C26, csl_deposits!B:B, csl_deposits!A:A, "NA", 0,1) -> 9 | C26: Bunyeroo Formation | D26: MEIH | E26: 250 | F26: Parachilna Gorge | G26: 138.53 | H26: -31.14 | I26: 233 | J26: Flinders Ranges | K26: 138.66497 | L26: -31.372568 | M26: granule cluster | O26: Wilpena | Q26: Bunyeroo | U26: Webb et al 1983 | V26: Haines 1986 | W26: Compston et al 1987 | X26: Young 1995 | Y26: Wallace et al 1996 | Z26: Gostin et al 2010 | AA26: Williams & Schmidt 2018 | AB26: Williams & Schmidt 2021
A27: 52 | B27: =_xlfn.XLOOKUP(C27, csl_deposits!B:B, csl_deposits!A:A, "NA", 0,1) -> 9 | C27: Bunyeroo Formation | D27: MEIH | E27: 92 | F27: Bunyeroo Gorge | G27: 138.86761 | H27: -31.467181 | I27: 233 | J27: Flinders Ranges | K27: 138.66497 | L27: -31.372568 | M27: granule cluster | O27: Wilpena | Q27: Bunyeroo | U27: Webb et al 1983 | V27: Haines 1986 | W27: Compston et al 1987 | X27: Young 1995 | Y27: Wallace et al 1996 | Z27: Gostin et al 2010 | AA27: Williams & Schmidt 2018 | AB27: Williams & Schmidt 2021
A28: 53 | B28: =_xlfn.XLOOKUP(C28, csl_deposits!B:B, csl_deposits!A:A, "NA", 0,1) -> 9 | C28: Bunyeroo Formation | D28: MEIH | E28: 92 | F28: Bunyeroo Gorge | G28: 138.86761 | H28: -31.467181 | I28: 233 | J28: Flinders Ranges | K28: 138.66497 | L28: -31.372568 | M28: granule cluster | O28: Wilpena | Q28: Bunyeroo | U28: Webb et al 1983 | V28: Haines 1986 | W28: Compston et al 1987 | X28: Young 1995 | Y28: Wallace et al 1996 | Z28: Gostin et al 2010 | AA28: Williams & Schmidt 2018 | AB28: Williams & Schmidt 2021
A29: 54 | B29: =_xlfn.XLOOKUP(C29, csl_deposits!B:B, csl_deposits!A:A, "NA", 0,1) -> 15 | C29: Dey Dey Mudstone | D29: MEIH | E29: 252 | F29: Munta-1 | G29: 131.94 | H29: -28.4 | I29: 331 | J29: Officer Basin | K29: 131.94 | L29: -28.4 | M29: granule cluster | O29: Ungoolya | Q29: Dey Dey | U29: Gostin et al 2010
A30: 55 | B30: =_xlfn.XLOOKUP(C30, csl_deposits!B:B, csl_deposits!A:A, "NA", 0,1) -> 15 | C30: Dey Dey Mudstone | D30: MEIH | E30: 253 | F30: Murnaroo-1 | G30: 132.2 | H30: -29.26 | I30: 331 | J30: Officer Basin | K30: 131.94 | L30: -28.4 | M30: granule cluster | O30: Ungoolya | Q30: Dey Dey | U30: Gostin et al 2010
A31: 58 | B31: =_xlfn.XLOOKUP(C31, csl_deposits!B:B, csl_deposits!A:A, "NA", 0,1) -> 18 | C31: Doushantuo glendonites | D31: MEIH | E31: 256 | F31: YD-4 | G31: 111.35 | H31: 30.33 | I31: 32 | J31: Yangtze Block | K31: 111.16 | L31: 30.79 | M31: glendonite | Q31: Doushantuo | S31: U2 | U31: Wang et al 2020 | V31: Yang et al 2021
A32: 59 | B32: =_xlfn.XLOOKUP(C32, csl_deposits!B:B, csl_deposits!A:A, "NA", 0,1) -> 18 | C32: Doushantuo glendonites | D32: MEIH | E32: 255 | F32: HJZK | G32: 112.21 | H32: 31.5 | I32: 32 | J32: Yangtze Block | K32: 111.16 | L32: 30.79 | M32: glendonite | Q32: Doushantuo | S32: U6 to U9 | U32: Wang et al 2020 | V32: Yang et al 2021
A33: 63 | B33: =_xlfn.XLOOKUP(C33, csl_deposits!B:B, csl_deposits!A:A, "NA", 0,1) -> 24 | C33: Fauquier Formation | D33: MEIH | E33: 257 | F33: Lincoln Quadrangle | G33: -77.64 | H33: 39.04 | I33: 334 | J33: Northern Virginia | K33: -77.64 | L33: 39.04 | M33: diamictite | O33: Lynchburg | P33: Upper Lynchburg | Q33: Fauquier | U33: Wehr & Glover 1985 | V33: Southworth et al 2009 | W33: Hebert et al 2010
A34: 64 | B34: =_xlfn.XLOOKUP(C34, csl_deposits!B:B, csl_deposits!A:A, "NA", 0,1) -> 24 | C34: Fauquier Formation | D34: MEIH | E34: 258 | F34: Marshall Quadrangle | G34: -77.84 | H34: 38.82 | I34: 334 | J34: Northern Virginia | K34: -77.64 | L34: 39.04 | M34: diamictite | O34: Lynchburg | P34: Upper Lynchburg | Q34: Fauquier | U34: Wehr & Glover 1985 | V34: Southworth et al 2009 | W34: Hebert et al 2010
A35: 65 | B35: =_xlfn.XLOOKUP(C35, csl_deposits!B:B, csl_deposits!A:A, "NA", 0,1) -> 47 | C35: Loch na Cille beds | D35: Ediacaran | E35: 269 | F35: Tayvallich Peninsula | G35: -5.7 | H35: 55.93 | I35: 332 | J35: Southern Highlands | K35: -7.14 | L35: 55.29 | M35: diamictite | N35: Dalradian | O35: Southern Highlands | S35: Loch na Cille beds | T35: Loch na Cille boulder beds | U35: Condon & Prave 2000 | V35: Dempster et al 2002 | W35: McCay et al 2006 | X35: Chumakov 2007 | Y35: Prave & Fallick 2011
A36: 66 | B36: =_xlfn.XLOOKUP(C36, csl_deposits!B:B, csl_deposits!A:A, "NA", 0,1) -> 35 | C36: Inishowen beds | D36: Ediacaran | E36: 262 | F36: Inishowen Peninsula | G36: -7.14 | H36: 55.29 | I36: 332 | J36: Southern Highlands | K36: -7.14 | L36: 55.29 | M36: diamictite | N36: Dalradian | O36: Southern Highlands | S36: Inishowen beds | T36: Inishowan beds | U36: Condon & Prave 2000 | V36: Dempster et al 2002 | W36: McCay et al 2006 | X36: Chumakov 2007 | Y36: Prave & Fallick 2011
A37: 68 | B37: =_xlfn.XLOOKUP(C37, csl_deposits!B:B, csl_deposits!A:A, "NA", 0,1) -> 92 | C37: Fengtai Formation | D37: Ediacaran | E37: 346 | F37: Bagongshan | G37: 116.78806 | H37: 32.647222 | I37: 348 | J37: North China Craton | K37: 116.78806 | L37: 32.647222 | M37: diamictite | Q37: Fengtai | U37: Yue et al 2025 | V37: Tan et al 2025
A38: 69 | B38: =_xlfn.XLOOKUP(C38, csl_deposits!B:B, csl_deposits!A:A, "NA", 0,1) -> 92 | C38: Fengtai Formation | D38: Ediacaran | E38: 347 | F38: Xiaomeiyao | G38: 115.92167 | H38: 32.271944 | I38: 348 | J38: North China Craton | K38: 116.78806 | L38: 32.647222 | M38: diamictite | Q38: Fengtai | U38: Yue et al 2025
A39: 70 | B39: =_xlfn.XLOOKUP(C39, csl_deposits!B:B, csl_deposits!A:A, "NA", 0,1) -> 64 | C39: Playa Hermosa Formation | D39: MEIH | E39: 353 | F39: Playa Hermosa | G39: -55.302907 | H39: -34.8333 | I39: 267 | J39: Piriapolis | K39: -55.28 | L39: -34.88 | M39: diamictite | O39: Maldonado | Q39: Playa Hermosa | R39: Lower Member | U39: Pazos et al 2011
A40: 74 | B40: =_xlfn.XLOOKUP(C40, csl_deposits!B:B, csl_deposits!A:A, "NA", 0,1) -> 18 | C40: Doushantuo glendonites | D40: MEIH | E40: 101 | F40: Zhangcunping | G40: 111.21 | H40: 31.29 | I40: 32 | J40: Yangtze Block | K40: 111.16 | L40: 30.79 | M40: glendonite | Q40: Doushantuo | S40: U6 | U40: Wang et al 2017 | V40: Zhou et al 2017 | W40: Wang et al 2020 | X40: Yang et al 2021
...

Sheet csl_deposits
A1: deposit_id | B1: deposit_name | C1: deposit_synonyms_correlatives | D1: deposit_type | E1: craton | F1: average_longitude | G1: average_latitude | H1: likely_interval | I1: likely_interval_notes | J1: deposit_score_WH02 | K1: deposit_score_WH02_source | L1: deposit_score_WH01 | M1: deposit_score_WH01_source | N1: deposit_score_Tindal2023 | O1: deposit_score_Tindal2023_notes | P1: tindal_2023_included | Q1: tindal_2023_id | R1: tindal_2023_age_max | S1: tindal_2023_age_max_unc | T1: tindal_2023_age_min | U1: tindal_2023_age_min_unc | V1: tindal_2023_evidence | W1: tindal_2023_notes | X1: youbi_2020_included | Y1: youbi_2020_glaciation | Z1: youbi_2020_age_max | AA1: youbi_2020_age_min | AB1: youbi_2020_notes | AC1: retallack_2022_included | AD1: retallack_2022_glaciation | AE1: retallack_2022_age_max | AF1: retallack_2022_age_min | AG1: retallack_2022_notes | AH1: wang_2023_included | AI1: wang_2023_id | AJ1: wang_2023_age_max | AK1: wang_2023_age_max_unc | AL1: wang_2023_age_min | AM1: wang_2023_age_min_unc | AN1: wang_2023_glaciation | AO1: wang_2023_notes | AP1: niu_2024_included | AQ1: niu_2024_id | AR1: niu_2024_facies | AS1: niu_2024_glaciation | AT1: niu_2024_age_max | AU1: niu_2024_age_min | AV1: niu_2024_notes
A2: 8 | B2: Bradore Formation | C2: sub-Cambrian pavement | D2: glacial | E2: Laurentia | H2: uncertain | I2: Likely pre-Cambrian; undulating surface expressed on Archaean gneiss | J2: 1 | K2: Tindal 2023 | L2: 1 | M2: Tindal 2023 | N2: 1 | P2: Yes | Q2: NF23 | T2: 485.4 | U2: 1.9 | V2: ★☆☆☆☆ grooved surfaces, and diamictite with rounded clasts from one lithological group | X2: No | AC2: Yes | AD2: Hankalchough | AE2: 555 | AF2: 549 | AG2: Evidence cited for deposits of this glaciation are frost boils; needle ice casts; dropped pebbles; low chemical index of alteration; glacial pavement; diamictite. | AH2: No | AP2: Yes | AQ2: 37 | AR2: Glacial erosion surface | AS2: Hankalchough | AT2: 562 | AU2: 551
A3: 29 | B3: Gwna Group | C3: Mona Group; Bodorgan Formation | D3: glacial | E3: Avalonia | H3: uncertain | I3: Following Schofield et al 2021; possibly Cambro-Ordovician. | J3: 2 | K3: WH02: see Supplementary Information | L3: 3 | M3: Tindal 2023 | N3: 3 | P3: Yes | Q3: NF18 | R3: 619 | S3: 6 | T3: 501 | U3: 10 | V3: ★★★☆☆ diamictite and dropstones with angular to rounded clasts from 3 lithological groups | X3: No | AC3: No | AH3: Yes | AI3: 9 | AJ3: 595 | AK3: 12 | AL3: 555 | AM3: 5 | AN3: GEG | AO3: Maximum age constraint from Rb-Sr whole-rock isochron on underlying metamorphic rock. Minimum age constraint from Rb-Sr whole-rock isochron of 550-560 Ma from metamorphic rock above. | AP3: Yes | AQ3: 40 | AR3: Cordillera-type mountain ice sheets | AS3: Gaskiers | AT3: 581 | AU3: 579 | AV3: Possible Gaskiers assignment.
A4: 35 | B4: Inishowen beds | C4: Inishowan beds; Inishowan Boulder Beds; Inishowen Boulder Beds | D4: glacial | E4: Laurentia | F4: -7.14 | G4: 55.29 | H4: uncertain | I4: Poorly constrained except by putative correlation with the Loch na Cille beds. Possibly MEIH or slightly older following radiometric constraints. | J4: 3 | K4: WH02: see Supplementary Information | L4: 0 | M4: Tindal 2023 rated 0; included here because it as included in other compilations. | N4: 0 | O4: Tindal 2023 rated 0; included here because it as included in other compilations. | P4: Yes | Q4: NE17 | V4: ☆☆☆☆☆ diamictite with clasts of unreported roundness from one lithological group | X4: No | AC4: No | AH4: Yes | AI4: 22 | AJ4: 590 | AL4: 570 | AN4: GEG | AO4: No detail provided for age constraints. Loch na Cille and Inishowan beds combined. | AP4: Yes | AQ4: 42 | AR4: Marine glacial | AS4: Gaskiers | AT4: 581 | AU4: 579 | AV4: Inishowan and Loch na Cille beds combined.
A5: 47 | B5: Loch na Cille beds | C5: Tayvallich Formation | D5: glacial | E5: Laurentia | F5: -5.7 | G5: 55.93 | H5: uncertain | I5: Poorly constrained except by putative correlation with the Inishowen beds. Possibly MEIH or slightly older following radiometric constraints. | J5: 2 | K5: WH02: see Supplementary Information | L5: 2 | M5: Tindal 2023 | N5: 2 | P5: Yes | Q5: NE16 | R5: 601 | S5: 4 | T5: 485.4 | U5: 1.9 | V5: ★★☆☆☆ diamictite with clasts of unreported roundness from 3 lithological groups | X5: Yes | Y5: Loch na Cille | Z5: 595 | AB5: Age constraints follow Halliday et al 1989 and Dempster et al 2002 | AC5: No | AH5: Yes | AI5: 22 | AJ5: 590 | AL5: 570 | AN5: GEG | AO5: No detail provided for age constraints. Loch na Cille and Inishowan beds combined. | AP5: Yes | AQ5: 42 | AR5: Marine glacial | AS5: Gaskiers | AT5: 581 | AU5: 579 | AV5: Inishowan and Loch na Cille beds combined.
A6: 57 | B6: Mount Lloyd George Formation | D6: glacial | E6: Laurentia | H6: uncertain | I6: Following Eisbacher 1981; Smith et al 2011. | J6: 3 | K6: Tindal 2023 | L6: 3 | M6: Tindal 2023 | N6: 3 | P6: Yes | Q6: NF4 | T6: 509 | U6: 5 | V6: ★★★☆☆ diamictite and dropstones with clasts of unreported roundness from 3 lithological groups, some of which are striated | X6: No | AC6: No | AH6: No | AP6: No
A7: 65 | B7: Pourpree de l'Ahnet Group | D7: glacial | E7: West Gondwana | H7: uncertain | I7: Poorly constrained; Deynoux et al 2006 and Chumakov 2009 infer a late Ediacaran (560 to 530 Ma) depositional age but the radiometric constraints they use are unreliable (see Bechiri-Benmerzoug et al 2017) and a Cryogenian age based on lithostratigraphy of the 'triad' deposits across the Taoudeni Basin may be more likely (Graham Shields pers. comm.) | J7: 4 | K7: Tindal 2023 | L7: 4 | M7: WH01: Tindal 2023 split into lower 4* and upper 2* diamictites; combined here. | N7: 4 | O7: Tindal 2023 split into lower 4* and upper 2* diamictites; combined here. | P7: Yes | Q7: NA4ab | R7: 560 | S7: 10 | T7: 530 | U7: 7 | V7: ★★★★☆ varves, and diamictite and dropstones with angular to rounded clasts from 3 lithological groups, some of which are facetted or striated | X7: No | AC7: No | AH7: Yes | AI7: 31 | AJ7: 560 | AK7: 10 | AL7: 530 | AN7: GEG | AO7: Maximum age constraint from U-Pb and Rb-Sr dating of granites. Minimum age constraint from tuff U-Pb and Ar-Ar dates. | AP7: Yes | AQ7: 32 | AR7: Mountain and terrestrial glacial | AS7: Hankalchough | AT7: 562 | AU7: 551 | AV7: Pourpree l'Ahnet and Fersiga groups combined.
A8: 69 | B8: Shaohuotong Formation | C8: Shaohuotonggou Group | D8: glacial | E8: North China | H8: uncertain | I8: Possibly older than 593 Ma following Tindal 2023. | J8: 0 | K8: Tindal 2023 | L8: 0 | M8: Tindal 2023 rated 0; included here because it as included in other compilations. | N8: 0 | P8: Yes | Q8: NC32 | T8: 593 | U8: 39 | V8: ☆☆☆☆☆ diamictite with clasts of unreported roundness from one lithological group | X8: No | AC8: No | AH8: No | AP8: Yes | AQ8: 15 | AR8: Marine glacial | AS8: uncertain | AV8: Included in compilation but not assigned to a glacial interval.
A9: 81 | B9: Vingerbreek Member | C9: Vingerbreek Unconformity; Nudaus Formation | D9: glacial | E9: Kalahari | H9: uncertain | I9: Commonly interpreted as Ediacaran; Baillie et al 2025 (unreviewed abstract) indicate a non-Ediacaran (Permo-Carboniferous, Dwyka Formation) assignation for the glacial parts of this deposit | J9: 3 | K9: WH01: see Supplementary Information | L9: 3 | M9: Tindal 2023 | N9: 3 | P9: Yes | Q9: NA24 | R9: 549 | S9: 1 | T9: 545 | U9: 0.01 | V9: ★★★☆☆ a small gouged surface, and diamictite with clasts of unreported roundness from one lithological group, some of which are facetted or striated | X9: Yes | Y9: Vingerbreek | AB9: Identified as post-Gaskiers but no other age constraints given | AC9: No | AH9: Yes | AI9: 20 | AJ9: 549 | AK9: 1 | AN9: GEG | AO9: Maximum age constraint from underlying Zaris Formation tuff zircon U-Pb date. No minimum age constraint. | AP9: Yes | AQ9: 33 | AR9: Palaeovalleys | AS9: Hankalchough | AT9: 562 | AU9: 551
A10: 82 | B10: Wegleszyn Tilloid | D10: glacial | E10: Baltica | H10: uncertain | I10: Following Brochwicz-Lewinski 1981. | J10: 2 | K10: Tindal 2023 | L10: 2 | M10: Tindal 2023 | N10: 2 | P10: Yes | Q10: NE23 | T10: 541 | U10: 1 | V10: ★★☆☆☆ diamictite and lonestones with rounded clasts from 3 lithological groups | X10: No | AC10: No | AH10: No | AP10: No
A11: 1 | B11: Antaq Polymictic Conglomerate | C11: Rubtayn Formation; Jibalah Group | D11: glacial | E11: Arabian Shield | F11: 44.22556 | G11: 23.71837 | H11: MEIH | J11: 2 | K11: WH02: see Supplementary Information | L11: 2 | M11: Tindal 2023 | N11: 2 | P11: Yes | Q11: NC4 | R11: 618 | S11: 0.01 | T11: 576 | U11: 5.6 | V11: ★★☆☆☆ diamictite with subrounded to rounded clasts from 3 lithological groups | X11: No | AC11: No | AH11: No | AP11: No
A12: 9 | B12: Bunyeroo Formation | D12: glacial | E12: East Gondwana | F12: 138.56 | G12: -31.43 | H12: MEIH | J12: 1 | K12: WH02: see Supplementary Information | L12: 1 | M12: Tindal 2023 | N12: 1 | P12: Yes | Q12: ND16c | R12: 657 | S12: 17 | T12: 593 | U12: 32 | V12: ★☆☆☆☆ lonestones with clasts of unreported roundness from one lithological group | X12: No | AC12: Yes | AD12: Gaskiers | AE12: 581 | AF12: 579 | AG12: Evidence cited for deposits of this glaciation are tillite; dropped pebbles; low chemical index of alteration; ice wedges; paleokarst. | AH12: Yes | AI12: 5 | AJ12: 588 | AK12: 35 | AL12: 570 | AN12: GEG | AO12: Maximum age constraint from Rb-Sr isochron on Stuart Shelf equivalent of Bunyeroo Formation. No specified minimum age constraint but noted that it is below the Wonoka Formation. | AP12: Yes | AQ12: 22 | AR12: Marine glacial | AS12: Gaskiers | AT12: 581 | AU12: 579
A13: 14 | B13: Croles Hill diamictite | D13: glacial | E13: East Gondwana | F13: 144.86249 | G13: -40.743828 | H13: MEIH | I13: Interbedded with volcanic units that are dated | J13: 3 | K13: WH02: see Supplementary Information | L13: 3 | M13: Tindal 2023 | N13: 3 | P13: Yes | Q13: ND20b | R13: 582 | S13: 4 | T13: 485.4 | U13: 5 | V13: ★★★☆☆ diamictite and lonestones with angular to rounded clasts from 3 lithological groups | X13: Yes | Y13: Gaskiers | Z13: 582 | AA13: 575 | AB13: Possibly assigned to Elatina glaciation; age constraints from Calver et al 2004 | AC13: No | AH13: Yes | AI13: 6 | AJ13: 582 | AK13: 4 | AN13: GEG | AO13: Maximum age constraint from 582 ± 4 Ma date of Calver et al 2004. No minimum age constraint. | AP13: Yes | AQ13: 23 | AR13: Lowland terrestrial glacial | AS13: Gaskiers | AT13: 581 | AU13: 579
A14: 15 | B14: Dey Dey Mudstone | D14: glacial | E14: East Gondwana | F14: 131.94 | G14: -28.4 | H14: MEIH | J14: 1 | K14: WH02: see Supplementary Information | L14: 2 | M14: Tindal 2023 | N14: 2 | P14: Yes | Q14: ND12 | V14: ★★☆☆☆ dropstones with clasts of unreported roundness from one lithological group | X14: No | AC14: No | AH14: No | AP14: No
A15: 18 | B15: Doushantuo glendonites | D15: glacial | E15: South China | F15: 111.35 | G15: 30.33 | H15: MEIH | K15: WH02: see Supplementary Information | L15: 0 | M15: Tindal 2023 implicit | O15: Tindal 2023 implicit 0: excluded glendonite occurrences. | P15: No | X15: No | AC15: No | AH15: No | AP15: No
A16: 24 | B16: Fauquier Formation | D16: glacial | E16: Laurentia | F16: -77.64 | G16: 39.04 | H16: MEIH | I16: Not well constrained | J16: 2 | K16: WH02: see Supplementary Information | L16: 2 | M16: Tindal 2023 | N16: 2 | P16: Yes | Q16: NF18b | R16: 715 | S16: 15 | T16: 570 | U16: 1 | V16: ★★☆☆☆ diamictite with angular to rounded clasts from 2 lithological groups | X16: No | AC16: Yes | AD16: Fauquier | AE16: 572 | AF16: 570 | AG16: Evidence cited for deposits of this glaciation are tillite; dropped pebbles; low chemical index of alteration; paleokarst. | AH16: Yes | AI16: 21 | AL16: 571 | AM16: 1 | AN16: GEG | AO16: Maximum age unconstrained. Minimum age constrained by zircon U-Pb TIMS date on felsic tuff. | AP16: Yes | AQ16: 41 | AR16: Pro-glacial fluvial outwash | AS16: Fauquier | AT16: 571 | AU16: 571
A17: 26 | B17: Gaskiers Formation | C17: Gaskiers diamictite | D17: glacial | E17: Avalonia | F17: -53.590889 | G17: 46.923334 | H17: MEIH | J17: 4 | K17: WH02: see Supplementary Information | L17: 4 | M17: Tindal 2023 | N17: 4 | P17: Yes | Q17: NF20 | R17: 580.9 | S17: 0.4 | T17: 579.88 | U17: 0.44 | V17: ★★★★☆ diamictite and dropstones with very angular to well-rounded clasts from 3 lithological groups, some of which are facetted or striated | X17: Yes | Y17: Gaskiers | Z17: 580.9 | AA17: 579.88 | AB17: Following age constraints of Pu et al 2016. | AC17: Yes | AD17: Gaskiers | AE17: 581 | AF17: 579 | AG17: Evidence cited for deposits of this glaciation are tillite; dropped pebbles; low chemical index of alteration; ice wedges; paleokarst. | AH17: Yes | AI17: 8 | AJ17: 580.9 | AK17: 0.4 | AL17: 579.88 | AM17: 0.44 | AN17: GEG | AO17: Cite a 50 cm 'cap carbonate' with d13C values -6 permille to -2 permille in the Harbour Main section and a 20 cm 'cap carbonate' with d13C values -8 permille to -5 permille in the Kitchuses section. | AP17: Yes | AQ17: 34 | AR17: Cordillera-type mountain ice sheets | AS17: Gaskiers | AT17: 581 | AU17: 579
A18: 27 | B18: Glussk Formation | C18: Vilchitsy Group; Vil'chitsy Group | D18: glacial | E18: Baltica | F18: 24.356558 | G18: 52.212443 | H18: MEIH | I18: Following Francovschi et al 2023; 2024 | J18: 4 | K18: WH02: see Supplementary Information | L18: 4 | M18: Tindal 2023 | N18: 4 | P18: Yes | Q18: NE24b | R18: 977 | S18: 6 | T18: 551 | U18: 4 | V18: ★★★★☆ varves, and diamictite and dropstones with angular to rounded clasts from 4 lithological groups, some of which are facetted or striated | X18: Yes | AB18: No age constraints given or plotted. | AC18: No | AH18: Yes | AI18: 13 | AJ18: 555 | AN18: GEG | AO18: Combined as Vil'chitsy Group. No maximum age constraint. Possibly minimum age constraint from U-Pb zircon date from Ust'Pinega. | AP18: Yes | AQ18: 4 | AR18: Lowland terrestrial glacial | AS18: Hankalchough | AT18: 562 | AU18: 551 | AV18: Possible Hankalchough assignment.
A19: 36 | B19: Iporanga Formation | D19: glacial | E19: Sao Francisco | F19: -48.6667 | G19: -24.5833 | H19: MEIH | I19: Poorly constrained; following Campanha et al 2008 | J19: 2 | K19: WH02: see Supplementary Information | L19: 2 | M19: WH01: ★★☆☆☆ Basal conglomerate with clasts of unreported roundness from 3 lithological groups. Note that Campanha et al 2008 interpret this unit as a non-glaciogenic basal conglomerate. | P19: No | X19: Yes | AB19: No age constraints given or plotted. | AC19: No | AH19: Yes | AI19: 25 | AJ19: 580 | AN19: GEG | AO19: Maximum age constraint from zircon U-Pb SHRIMP date. No minimum age constraint. | AP19: Yes | AQ19: 45 | AR19: Marine glacial | AS19: uncertain | AV19: Included in compilation but not assigned to a glacial interval.
A20: 38 | B20: Izdar Member | C20: Ouarzazate Group [but note disctinct from younger Ouarzazate Group deposits]; Aourz Formation; Bou Azzer tillite | D20: glacial | E20: West Gondwana | F20: -7.43 | G20: 30.52 | H20: MEIH | J20: 4 | K20: WH02: see Supplementary Information | L20: 3 | M20: Tindal 2023 | N20: 3 | P20: Yes | Q20: NA1b | R20: 592.31 | S20: 0.18 | T20: 574.9 | U20: 3 | V20: ★★★☆☆ basement roche moutoneé, and diamictite with very angular to well-rounded clasts from 2 lithological groups, some of which are facetted | X20: No | AB20: Includes the Ouarzazate Group but not Izdar Member specifically | AC20: No | AG20: Includes the Ouarzazate Group but not Izdar Member specifically | AH20: No | AO20: Includes the Ouarzazate Group but not Izdar Member specifically | AP20: No | AV20: Includes the Aourz Formation but not the Izdar Member and references Vernhet et al 2012 and Youbi et al 2020
A21: 40 | B21: Koyva Formation | C21: Koiva Formation | D21: glacial | E21: Baltica | F21: 58.87 | G21: 58.51 | H21: MEIH | J21: 3 | K21: WH02: see Supplementary Information | L21: 3 | M21: Tindal 2023 | N21: 3 | P21: Yes | Q21: NE29c | R21: 671 | S21: 24 | T21: 557 | U21: 13 | V21: ★★★☆☆ diamictite and dropstones with clasts of unreported roundness from one lithological group, some of which are striated | X21: No | AC21: Yes | AD21: Fauquier | AE21: 572 | AF21: 570 | AG21: Evidence cited for deposits of this glaciation are tillite; dropped pebbles; low chemical index of alteration; paleokarst. | AH21: Yes | AI21: 15 | AJ21: 598.1 | AK21: 6 | AL21: 567.2 | AM21: 3.9 | AN21: GEG | AO21: Maximum age constraint from tuff zircon U-Pb. Minimum age constraint from tuff zircon U-Pb. Combined Tany, Koiva, and Lower Starye Pechi formations; separated here. | AP21: Yes | AQ21: 7 | AR21: Marine glacial | AS21: Gaskiers | AT21: 581 | AU21: 579 | AV21: Combined Tany and Koiva formations; separated here.
A22: 44 | B22: Las Ventanas Formation | D22: glacial | E22: Rio de Plata | F22: -55.26 | G22: -34.71 | H22: MEIH | J22: 4 | K22: WH02: see Supplementary Information | L22: 3 | M22: Tindal 2023 | N22: 3 | P22: Yes | Q22: NG5 | R22: 590 | S22: 16 | T22: 578 | U22: 4.3 | V22: ★★★☆☆ diamictite and lonestones with angular to subrounded clasts from 3 lithological groups, some of which are facetted or striated | X22: No | AC22: No | AH22: Yes | AI22: 24 | AJ22: 615 | AK22: 30 | AL22: 579 | AM22: 1.5 | AN22: GEG | AO22: Maximum age constraint from K-Ar on basalt. Minimum age constraitnt from Ar-Ar on post-collisional plutons. | AP22: Yes | AQ22: 44 | AR22: Marine glacial | AS22: Gaskiers | AT22: 581 | AU22: 579
A23: 50 | B23: Mall Bay Formation | D23: glacial | E23: Avalonia | F23: -53.74 | G23: 47.04 | H23: MEIH | J23: 4 | K23: WH02: see Supplementary Information | L23: 2 | M23: WH01: ★★☆☆☆ subrounded dropstones from 2 lithological groups, some of which are facetted. Evidence (Fitzgerald et al 2024) not originally available. | P23: No | X23: No | AC23: No | AH23: No | AP23: No
A24: 64 | B24: Playa Hermosa Formation | D24: glacial | E24: Paraguay Belt | F24: -55.302907 | G24: -34.8333 | H24: MEIH | J24: 3 | K24: WH02: see Supplementary Information | L24: 3 | M24: Tindal 2023 | N24: 3 | P24: Yes | Q24: NG7 | R24: 594 | S24: 16 | T24: 578 | U24: 4.3 | V24: ★★★☆☆ rhythmite (possibly varves), and diamictite and dropstones with angular to subrounded clasts from 3 lithological groups | X24: No | AC24: No | AH24: No | AP24: No
A25: 68 | B25: Serra Azul Unit A | D25: glacial | E25: Amazonia | F25: -56.513986 | G25: -13.80137 | H25: MEIH | I25: Tentative assignment within large uncertainty of dates | J25: 4 | K25: WH02: see Supplementary Information | L25: 4 | M25: Tindal 2023 | N25: 4 | P25: Yes | Q25: NG3b | R25: 640 | S25: 15 | T25: 528 | U25: 26 | V25: ★★★★☆ rhythmites with tidal bundles, and diamictite with very angular to well-rounded clasts from 4 lithological groups, some of which are facetted or striated | X25: Yes | Y25: unnamed | AB25: No age constraints given or plotted. | AC25: No | AH25: Yes | AI25: 1 | AJ25: 630 | AN25: GEG | AO25: No age constraint details provided. No minimum age constraint. | AP25: Yes | AQ25: 43 | AR25: Palaeovalleys | AS25: Gaskiers | AT25: 581 | AU25: 579 | AV25: Possible Gaskiers assignment.
A26: 72 | B26: Squantum diamictite | C26: Roxbury Conglomerate | D26: glacial | E26: Avalonia | F26: -71.079627 | G26: 42.301702 | H26: MEIH | J26: 2 | K26: WH02: see Supplementary Information | L26: 4 | M26: Tindal 2023 | N26: 4 | P26: Yes | Q26: NF19 | R26: 596.39 | S26: 0.79 | T26: 509 | U26: 5 | V26: ★★★★☆ possible varves, and diamictite and lonestones with angular to subrounded clasts from 4 lithological groups, some of which are striated | X26: Yes | Y26: Squantum | Z26: 595.5 | AA26: 565 | AB26: Following age constraints of Thompson & Bowring 2000 and Thompson et al 2014 | AC26: Yes | AD26: Gaskiers | AE26: 581 | AF26: 579 | AG26: Evidence cited for deposits of this glaciation are tillite; dropped pebbles; low chemical index of alteration; ice wedges; paleokarst. | AH26: Yes | AI26: 10 | AJ26: 595.5 | AK26: 2 | AL26: 570 | AN26: GEG | AO26: Maximum age from U-Pb date on tuff clast in diamictite. Minimum age given as ~570 Ma or younger? | AP26: Yes | AQ26: 38 | AR26: Deep marine | AS26: Gaskiers | AT26: 581 | AU26: 579
A27: 73 | B27: Starye Pechi Formation | D27: glacial | E27: Baltica | F27: 58.87 | G27: 58.51 | H27: MEIH | I27: Could be interpreted as LEGH following tentative chemostratigraphic constraints - see Supplementary Information | J27: 3 | K27: WH02: see Supplementary Information | L27: 3 | M27: Tindal 2023 | N27: 3 | P27: Yes | Q27: NE29d | R27: 671 | S27: 24 | T27: 557 | U27: 13 | V27: ★★★☆☆ diamictite and dropstones with clasts of unreported roundness from 2 lithological groups, some of which are striated | X27: Yes | AB27: No age constraints given or plotted. | AC27: Yes | AD27: Bou Azzer | AE27: 566 | AF27: 564 | AG27: Evidence cited for deposits of this glaciation are dropped pebbles; low chemical index of alteration; diamictite. | AH27: Yes | AI27: 15 | AJ27: 598.1 | AK27: 6 | AL27: 567.2 | AM27: 3.9 | AN27: GEG | AO27: Maximum age constraint from tuff zircon U-Pb. Minimum age constraint from tuff zircon U-Pb. Combined Tany, Koiva, and Lower Starye Pechi formations; separated here. | AP27: Yes | AQ27: 6 | AR27: Marine glacial | AS27: Bou Azzer | AT27: 565 | AU27: 560 | AV27: Combined Starye Pechi and Sylvitsa Group; separated here and Sylvitsa Group not considered to be plausibly Gaskiers in age.
A28: 76 | B28: Tany Formation | D28: glacial | E28: Baltica | F28: 58.87 | G28: 58.51 | H28: MEIH | J28: 3 | K28: WH02: see Supplementary Information | L28: 4 | M28: WH01: Tindal 2023 split into lower 4* and upper 2* diamictites; combined here. | N28: 4 | O28: Tindal 2023 split into lower 4* and upper 2* diamictites; combined here. | P28: Yes | Q28: NE29ab | R28: 671 | S28: 24 | T28: 559 | U28: 16 | V28: ★★★★☆ diamictite and dropstones with clasts of unreported roundness from 4 lithological groups, some of which are striated (upper member). ★★☆☆☆ diamictite and dropstones with clasts of unreported roundness from one lithological group (lower member). | X28: Yes | AB28: No age constraints given or plotted. | AC28: Yes | AD28: Gaskiers | AE28: 581 | AF28: 579 | AG28: Evidence cited for deposits of this glaciation are tillite; dropped pebbles; low chemical index of alteration; ice wedges; paleokarst. | AH28: Yes | AI28: 15 | AJ28: 598.1 | AK28: 6 | AL28: 567.2 | AM28: 3.9 | AN28: GEG | AO28: Maximum age constraint from tuff zircon U-Pb. Minimum age constraint from tuff zircon U-Pb. Combined Tany, Koyva, and Lower Starye Pechi formations; separated here. | AP28: Yes | AQ28: 7 | AR28: Marine glacial | AS28: Gaskiers | AT28: 581 | AU28: 579 | AV28: Combined Tany and Koyva formations; separated here.
A29: 77 | B29: Tiddiline Group | D29: glacial | E29: West Gondwana | F29: -6.51 | G29: 30.56 | H29: MEIH | J29: 4 | K29: WH02: see Supplementary Information | L29: 3 | M29: Tindal 2023 | N29: 3 | P29: Yes | Q29: NA1a | R29: 592.84 | S29: 0.17 | T29: 579.4 | U29: 1.2 | V29: ★★★☆☆ possible varves, and diamictite with angular to rounded clasts from 2 lithological groups, some of which are facetted or striated | X29: Yes | Y29: Tiddiline | Z29: 593 | AA29: 579 | AB29: Age constraints cite Letsch et al 2018 | AC29: No | AG29: Possibly but not explicitly included in Ouarzazate Group sediments. | AH29: Yes | AI29: 29 | AJ29: 592.31 | AK29: 0.18 | AL29: 579.4 | AM29: 1.2 | AN29: GEG | AO29: Maximum and minimum age constraints from U-Pb zircons. | AP29: Yes | AQ29: 31 | AR29: Mountain and terrestrial glacial | AS29: Gaskiers | AT29: 581 | AU29: 579 | AV29: Possible Gaskiers assignment.
A30: 79 | B30: Trinity diamictite | C30: Rocky Harbour Group | D30: glacial | E30: Avalonia | F30: -53.37978 | G30: 48.376619 | H30: MEIH | J30: 4 | K30: WH02: see Supplementary Information | L30: 4 | M30: Tindal 2023 | N30: 4 | P30: Yes | Q30: NF21 | R30: 579.63 | S30: 0.15 | T30: 579.24 | U30: 0.17 | V30: ★★★★☆ diamictite and dropstones with well-rounded clasts from 3 lithological groups, some of which are striated | X30: Yes | Y30: Gaskiers | Z30: 579.63 | AA30: 579.88 | AB30: Following age constraints of Pu et al 2016 | AC30: No | AH30: No | AP30: Yes | AQ30: 35 | AR30: Cordillera-type mountain ice sheets | AS30: Gaskiers | AT30: 581 | AU30: 579
A31: 85 | B31: Xichangjing Formation | D31: glacial | E31: Altaids | F31: 96.1 | G31: 41.9 | H31: MEIH | J31: 4 | K31: WH02: see Supplementary Information | L31: 4 | M31: WH01: ★★★★☆ Deformed beds interpreted as glaciotectonism, and diamictite with subangular to rounded clasts from 4 lithological groups, some of which are facetted or striated. Evidence (Niu et al 2024) not originally available. | P31: No | X31: No | AC31: No | AH31: No | AP31: Yes | AQ31: 13 | AR31: Cordillera-type mountain ice sheets | AS31: Gaskiers | AT31: 581 | AU31: 579
A32: 89 | B32: Zukow Formation | C32: Zukowska Formation; Białystok Formation | D32: glacial | E32: Baltica | F32: 23.338792 | G32: 51.607848 | H32: MEIH | I32: Following Francovschi et al 2023; 2024 | J32: 2 | K32: WH02: see Supplementary Information | L32: 2 | M32: Tindal 2023 | N32: 2 | P32: Yes | Q32: NE22 | T32: 485.4 | U32: 1.9 | V32: ★★☆☆☆ diamictite with subangular to rounded clasts from 2 lithological groups, some of which are facetted | X32: No | AC32: No | AH32: No | AP32: No
A33: 93 | B33: Mercantile diamictite | C33: Rocky Harbour Group | D33: glacial | E33: Avalonia | F33: -53.578495 | G33: 48.357598 | H33: MEIH | I33: Following dates and correlations of Gomez et al 2025a,b, 2026 | J33: 4 | K33: WH02: see Supplementary Information | M33: Insufficient information published at time of submission | P33: No | X33: No | AC33: No | AH33: No | AP33: No
A34: 2 | B34: Baykonur Formation | C34: Baikonur Formation; Dzetymtay Formation; Rang Formation [sic] | D34: glacial | E34: Altaids | H34: LEIH | I34: Historically poorly constrained; often assumed to be late Ediacaran which is now supported by detrital zircon U-Pb dates by Alexeiev et al 2025 | J34: 4 | K34: Tindal 2023 | L34: 4 | M34: Tindal 2023 | N34: 4 | P34: Yes | Q34: NC14 | R34: 629 | S34: 8 | T34: 509 | U34: 5 | V34: ★★★★☆ diamictite and dropstones with angular to rounded clasts from 3 lithological groups, some of which are facetted or striated | X34: No | AC34: Yes | AD34: Hankalchough | AE34: 555 | AF34: 549 | AG34: Evidence cited for deposits of this glaciation are frost boils; needle ice casts; dropped pebbles; low chemical index of alteration; glacial pavement; diamictite. | AH34: Yes | AI34: 27 | AJ34: 560 | AL34: 560 | AN34: GEG | AO34: Age given as approximately 560 Ma following regional stratigraphy. | AP34: Yes | AQ34: 10 | AR34: Cordillera-type mountain ice sheets | AS34: Hankalchough | AT34: 562 | AU34: 551 | AV34: Possible Hankalchough assignment.
A35: 4 | B35: Billy Springs Formation | D35: glacial | E35: East Gondwana | H35: LEIH | J35: 3 | K35: Tindal 2023 | L35: 3 | M35: Tindal 2023 | N35: 3 | P35: Yes | Q35: ND15 | R35: 794 | S35: 4 | T35: 541 | U35: 1 | V35: ★★★☆☆ rhythmite (possibly varves), and diamictite and dropstones with angular to subrounded clasts from 2 lithological groups, some of which are facetted | X35: No | AC35: Yes | AD35: Bou Azzer | AE35: 566 | AF35: 564 | AG35: Evidence cited for deposits of this glaciation are dropped pebbles; low chemical index of alteration; diamictite. | AH35: Yes | AI35: 4 | AJ35: 562 | AN35: GEG | AO35: Maximum age constraint from maximum age of the underlying Wonoka Formation. No minimum age constraint. | AP35: Yes | AQ35: 20 | AR35: Marine glacial | AS35: Bou Azzer | AT35: 565 | AU35: 560
A36: 16 | B36: Dhaiqa Formation | D36: glacial | E36: Arabian Shield | H36: LEIH | J36: 3 | K36: Tindal 2023 | L36: 3 | M36: Tindal 2023 | N36: 3 | P36: Yes | Q36: NC3b | R36: 570 | S36: 4.6 | T36: 560 | U36: 4 | V36: ★★★☆☆ diamictite and dropstones with subrounded to rounded clasts from 3 lithological groups | X36: Yes | Y36: unnamed | Z36: 570 | AB36: Age constraints follow Vickers-Rich & Fedonkin 2007 and Miller et al 2008; possible confusion over interpretation of Vickers-Rich & Fedonkin date as being pre-/syn-depositional rather than post-depositional. | AC36: No | AH36: Yes | AI36: 2 | AJ36: 560 | AN36: GEG | AO36: Maximum age constraint from U-Pb date of Vickers-Rich et al 2010. No minimum age constraint provided. | AP36: Yes | AQ36: 25 | AR36: Cordillera-type mountain ice sheets | AS36: Bou Azzer | AT36: 565 | AU36: 560 | AV36: Possible Bou Azzer assingment.
A37: 28 | B37: Granville Formation | D37: glacial | E37: Cadomia | H37: LEIH | J37: 3 | K37: Tindal 2023 | L37: 3 | M37: Tindal 2023 | N37: 3 | P37: Yes | Q37: NE19 | T37: 617 | U37: 12 | V37: ★★★☆☆ diamictite with rounded to well-rounded clasts from 3 lithological groups, some of which are striated | X37: Yes | Y37: Granville | AB37: No age constraints given or plotted. | AC37: No | AH37: No | AP37: Yes | AQ37: 27 | AR37: Cordillera-type mountain ice sheets | AS37: Bou Azzer | AT37: 565 | AU37: 560
A38: 30 | B38: Hankalchough Formation | C38: Quruqtagh Group | D38: glacial | E38: Tarim | H38: LEIH | J38: 3 | K38: WH01 | L38: 3 | M38: WH01: ★★★☆☆ diamictite and dropstones with angular clasts from 3 lithological groups. | N38: 2 | P38: Yes | Q38: NC20d | R38: 615 | S38: 6 | T38: 541 | U38: 1 | V38: ★★☆☆☆ diamictite with angular clasts from 3 lithological groups | X38: Yes | AB38: No age constraints given or plotted. | AC38: Yes | AD38: Hankalchough | AE38: 555 | AF38: 549 | AG38: Evidence cited for deposits of this glaciation are frost boils; needle ice casts; dropped pebbles; low chemical index of alteration; glacial pavement; diamictite. | AH38: Yes | AI38: 28 | AJ38: 562 | AN38: GEG | AO38: Maximum age constraint from termination of Shuram carbon isotope excursion. No minimum age constraint. | AP38: Yes | AQ38: 14 | AR38: Terrestrial glacial | AS38: Hankalchough | AT38: 562 | AU38: 551
A39: 32 | B39: Hongtiegou Formation | D39: glacial | E39: Qaidam | H39: LEIH | I39: Following Wang et al 2021 PrecRes; assumption that deposition was close before fossil-bearing Zhoujieshan Formation | J39: 0 | K39: Tindal 2023; retained as low score may reflect lack of published detail | L39: 0 | M39: Tindal 2023 | N39: 0 | P39: Yes | Q39: NC31 | R39: 1640 | S39: 15 | T39: 509 | U39: 5 | V39: ☆☆☆☆☆ diamictite with subangular to subrounded clasts from one lithological group | X39: No | AC39: Yes | AD39: Hankalchough | AE39: 555 | AF39: 549 | AG39: Evidence cited for deposits of this glaciation are frost boils; needle ice casts; dropped pebbles; low chemical index of alteration; glacial pavement; diamictite. | AH39: Yes | AI39: 17 | AJ39: 560 | AL39: 560 | AN39: GEG | AO39: Age given as approximately 560 Ma. Fossil evidence used to suggest older than 547 Ma in the notes. | AP39: Yes | AQ39: 16 | AR39: Terrestrial and marine glacial | AS39: Hankalchough | AT39: 562 | AU39: 551
A40: 33 | B40: Hrushka Formation | C40: Gruska Formation; Slutsk-Kholonevychi diamictite | D40: glacial | E40: Baltica | H40: LEIH | J40: 3 | K40: WH01 | L40: 3 | M40: WH01: ★★★☆☆ rhythmically banded shales (possibly varves), and diamictite with rounded to angular clasts from 3 lithological groups, some of which are facetted. | N40: 1 | P40: Yes | Q40: NE25 | R40: 1018 | S40: 20 | T40: 573 | U40: 14 | V40: ★☆☆☆☆ diamictite with angular to subangular clasts from 2 lithological groups | X40: No | AC40: No | AH40: No | AP40: No
...

Sheet csl_age_constraints
A1: date_id | B1: deposit_id | C1: deposit_name | D1: sample_id | E1: constraint_position | F1: constraint_position_notes | G1: constraint_wrt_csl | H1: constraint_type | I1: constraint_date_lithology | J1: constraint_date_type | K1: constraint_date_system | L1: constraint_age_ma | M1: constraint_age_ma_unc | N1: d13c_excursion | O1: d13c_excursion_position | P1: radiometric_date_method | Q1: radiometric_date_mineral | R1: radiometric_date_gts2020_id | S1: radiometric_date_ma | T1: radiometric_date_ma_x | U1: radiometric_date_ma_y | V1: radiometric_date_ma_z | W1: radiometric_date_ma_mswd | X1: radiometric_date_description | Y1: radiometric_date_notes | Z1: sample_group | AA1: sample_subgroup | AB1: sample_formation | AC1: sample_member | AD1: sample_unit | AE1: sample_bed | AF1: additional_notes | AG1: reference1 | AH1: reference2 | AI1: reference3 | AJ1: reference4
A2: 1 | B2: =_xlfn.XLOOKUP(C2, csl_deposits!B:B, csl_deposits!A:A, "NA", 0,1) -> 1 | C2: Antaq Polymictic Conglomerate | D2: S02-04 | E2: above | G2: minimum | H2: Radiometric date | I2: pyroclastic tuff | J2: eruption | K2: U-Pb | L2: 579 | M2: 17 | P2: LA-ICP-MS | Q2: igneous zircon | S2: 579 | T2: 17 | X2: Igneous zircon U-Pb LA-ICP-MS date. | Z2: Jibalah | AB2: Muraykhah | AG2: Nettle et al 2014
A3: 2 | B3: =_xlfn.XLOOKUP(C3, csl_deposits!B:B, csl_deposits!A:A, "NA", 0,1) -> 1 | C3: Antaq Polymictic Conglomerate | D3: S02-23 | E3: above | G3: minimum | H3: Radiometric date | I3: pyroclastic tuff | J3: maximum | K3: U-Pb | L3: 604 | M3: 18 | P3: LA-ICP-MS | Q3: igneous zircon | S3: 604 | T3: 18 | X3: Igneous zircon U-Pb LA-ICP-MS date. | Y3: Interpreted as an inherited zircon date due to stratigraphic incongruence. | Z3: Jibalah | AB3: Muraykhah | AG3: Nettle et al 2014
A4: 3 | B4: =_xlfn.XLOOKUP(C4, csl_deposits!B:B, csl_deposits!A:A, "NA", 0,1) -> 1 | C4: Antaq Polymictic Conglomerate | D4: WP045 | E4: below | F4: Sample from basement beneath candidate glaciogenic deposit. | G4: maximum | H4: Radiometric date | I4: porphyritic microgranite | J4: intrusion | K4: U-Pb | L4: 618.17 | M4: 0.89 | P4: CA-TIMS | Q4: igneous zircon | S4: 618.17 | T4: 0.2 | U4: 0.62 | V4: 0.89 | W4: 0.65 | X4: Igneous zircon U-Pb CA-TIMS date on porphyritic microgranite in the basement below the Rubtayn Formation | AD4: porphyritic microgranite | AG4: Nettle et al 2014
A5: 4 | B5: =_xlfn.XLOOKUP(C5, csl_deposits!B:B, csl_deposits!A:A, "NA", 0,1) -> 1 | C5: Antaq Polymictic Conglomerate | D5: WP65 | E5: contemporaneous | G5: deposition | H5: Radiometric date | I5: pyroclastic tuff | J5: eruption | K5: U-Pb | L5: 596 | M5: 17 | P5: LA-ICP-MS | Q5: igneous zircon | S5: 596 | T5: 17 | X5: Igneous zircon U-Pb LA-ICP-MS date. | Z5: Jibalah | AB5: Rubtayn | AC5: upper Rubtayn | AG5: Nettle et al 2014
A6: 5 | B6: =_xlfn.XLOOKUP(C6, csl_deposits!B:B, csl_deposits!A:A, "NA", 0,1) -> 2 | C6: Baykonur Formation | E6: above | F6: Overyling Kokbulak and Koktal formations contain early Cambrian fossils | G6: minimum | H6: Biostratigraphy | J6: minimum | L6: 538.8 | AB6: Kokbulak | AG6: Chumakov 2009 | AH6: Chumakov 2011c
A7: 6 | B7: =_xlfn.XLOOKUP(C7, csl_deposits!B:B, csl_deposits!A:A, "NA", 0,1) -> 2 | C7: Baykonur Formation | E7: above | F7: Overyling Kokbulak and Koktal formations contain early Cambrian fossils | G7: minimum | H7: Biostratigraphy | J7: minimum | L7: 538.8 | AB7: Kokbulak | AG7: Chumakov 2009 | AH7: Chumakov 2011c
A8: 7 | B8: =_xlfn.XLOOKUP(C8, csl_deposits!B:B, csl_deposits!A:A, "NA", 0,1) -> 2 | C8: Baykonur Formation | E8: above | F8: Overyling Kokbulak and Koktal formations contain early Cambrian fossils | G8: minimum | H8: Biostratigraphy | J8: minimum | L8: 538.8 | AB8: Kokbulak | AG8: Chumakov 2009 | AH8: Chumakov 2011c
A9: 8 | B9: =_xlfn.XLOOKUP(C9, csl_deposits!B:B, csl_deposits!A:A, "NA", 0,1) -> 2 | C9: Baykonur Formation | D9: KG21 | E9: below | F9: Diamictite correlated with the Baykonur Formation | G9: maximum | H9: Radiometric date | I9: diamictite | J9: maximum | K9: U-Pb | L9: 629 | M9: 8 | P9: LA-ICP-MS | Q9: detrital zircon | S9: 629 | T9: 8 | X9: Detrital zircon U-Pb LA-ICP-MS date from diamictite matrix | AB9: Djetymtau | AG9: Rojas-Agramonte et al 2014
A10: 9 | B10: =_xlfn.XLOOKUP(C10, csl_deposits!B:B, csl_deposits!A:A, "NA", 0,1) -> 2 | C10: Baykonur Formation | D10: 1B-1 | E10: contemporaneous | F10: Upper part of the Baykonur Formation diamictite | G10: maximum | H10: Radiometric date | I10: diamictite | J10: maximum | K10: U-Pb | L10: 581 | M10: 6 | P10: LA-ICP-MS | Q10: detrital zircon | S10: 581 | T10: 6 | X10: Detrital zircon U-Pb LA-ICP-MS date from diamictite wholerock | AB10: Baykonur | AC10: upper Baykonur | AG10: Alexeiev et al 2025
A11: 10 | B11: =_xlfn.XLOOKUP(C11, csl_deposits!B:B, csl_deposits!A:A, "NA", 0,1) -> 2 | C11: Baykonur Formation | D11: 1A-1 | E11: contemporaneous | F11: Upper part of the Baykonur Formation diamictite | G11: maximum | H11: Radiometric date | I11: diamictite | J11: maximum | K11: U-Pb | L11: 556 | M11: 8 | P11: LA-ICP-MS | Q11: detrital zircon | S11: 556 | T11: 8 | X11: Detrital zircon U-Pb LA-ICP-MS date from diamictite wholerock | AB11: Baykonur | AC11: upper Baykonur | AG11: Alexeiev et al 2025
A12: 11 | B12: =_xlfn.XLOOKUP(C12, csl_deposits!B:B, csl_deposits!A:A, "NA", 0,1) -> 4 | C12: Billy Springs Formation | E12: above | F12: Billy Springs Formation underlies the Rawnsley Quartzite including the fossiliferous Ediacara Member which is of late Ediacaran age. | G12: minimum | H12: Biostratigraphy | J12: minimum | L12: 538.8 | AG12: Jenkins 2011
A13: 12 | B13: =_xlfn.XLOOKUP(C13, csl_deposits!B:B, csl_deposits!A:A, "NA", 0,1) -> 4 | C13: Billy Springs Formation | E13: below | F13: Date from Busch et al 2023 in Gametrail Formation; Shuram-correlated Wonoka excursion in the underlying Wonoka Formation. | G13: maximum | H13: CIE | I13: carbonate | J13: maximum | K13: 13C | L13: 566.9 | M13: 3.5 | N13: Shuram | O13: below deposit | AB13: Wonoka | AG13: Jenkins 2011 | AH13: Rooney et al 2020 | AI13: Yang et al 2021 | AJ13: Busch et al 2023
A14: 13 | B14: =_xlfn.XLOOKUP(C14, csl_deposits!B:B, csl_deposits!A:A, "NA", 0,1) -> 5 | C14: Blon Formation | D14: KOB-26 | E14: above | F14: From overlying Volyn Group. | G14: minimum | H14: Radiometric date | I14: tuff | J14: eruption | K14: U-Pb | L14: 569.36 | M14: 0.29 | P14: CA-ID-TIMS | Q14: igneous zircon | S14: 569.36 | T14: 0.29 | W14: 0.05 | X14: Tuff zircon U-Pb CA-ID-TIMS date | Z14: Volyn | AB14: Rataychitsy | AF14: Likely Cryogenian following Francovschi et al 2023; 2024 | AG14: Srodon et al 2023 | AH14: Francovschi et al 2023 | AI14: Francovschi et al 2024
A15: 14 | B15: =_xlfn.XLOOKUP(C15, csl_deposits!B:B, csl_deposits!A:A, "NA", 0,1) -> 5 | C15: Blon Formation | D15: KOB-25 | E15: above | F15: From overlying Volyn Group. | G15: minimum | H15: Radiometric date | I15: tuff | J15: eruption | K15: U-Pb | L15: 569.4 | M15: 0.12 | P15: CA-ID-TIMS | Q15: igneous zircon | S15: 569.4 | T15: 0.12 | W15: 1.35 | X15: Tuff zircon U-Pb CA-ID-TIMS date | Z15: Volyn | AB15: Rataychitsy | AF15: Likely Cryogenian following Francovschi et al 2023; 2024 | AG15: Srodon et al 2023 | AH15: Francovschi et al 2023 | AI15: Francovschi et al 2024
A16: 15 | B16: =_xlfn.XLOOKUP(C16, csl_deposits!B:B, csl_deposits!A:A, "NA", 0,1) -> 8 | C16: Bradore Formation | E16: above | F16: Below lowest occurring Cambrian body fossils in the Forteau Formation and earliest Cambrian trace fossils in the Bradore Formation | G16: minimum | H16: Biostratigraphy | J16: minimum | L16: 538.8 | AG16: Swett 1981 | AH16: Knight et al 2017
A17: 16 | B17: =_xlfn.XLOOKUP(C17, csl_deposits!B:B, csl_deposits!A:A, "NA", 0,1) -> 9 | C17: Bunyeroo Formation | E17: above | F17: Wonoka excursion correlated to the Shuram excursion begins in the Wonoka Formation above the Bunyeroo Formation | G17: minimum | H17: CIE | J17: minimum | K17: 13C | L17: 574 | M17: 4.7 | N17: Shuram | O17: above deposit | AB17: Wonoka | AG17: Williams & Schmidt 2018 | AH17: Rooney et al 2020 | AI17: Yang et al 2021
A18: 17 | B18: =_xlfn.XLOOKUP(C18, csl_deposits!B:B, csl_deposits!A:A, "NA", 0,1) -> 9 | C18: Bunyeroo Formation | E18: below | F18: Stratigraphically above latest Cryogenian strata. | G18: maximum | H18: Correlation | J18: maximum | L18: 635 | M18: 0 | AG18: Williams & Schmidt 2018 | AH18: Rooney et al 2020 | AI18: Yang et al 2021
A19: 18 | B19: =_xlfn.XLOOKUP(C19, csl_deposits!B:B, csl_deposits!A:A, "NA", 0,1) -> 10 | C19: Chameis Gate Member | E19: above | F19: Minimum age of island arc accretion metamorphism. | G19: minimum | H19: Radiometric date | I19: amphibole | J19: minimum | K19: Ar-Ar | L19: 575 | M19: 2 | Q19: metamorphic amphibole | S19: 575 | T19: 2 | X19: Ar-Ar date on HP metamorphic amphibole generation in metagabbro | Z19: Bakers Bay Suite | AD19: metagabbro | AG19: Frimmel & Frank 1998 | AH19: Frimmel 2011a
